Workbook

Sheet Dashboard
B2: TAX TRACKER 2026 — IESKANDAR ZULQARNAIN BIN GHAZALI
B3: Assessment Year 2026 | Resident | Single (Bujang) | Auto-updated from all sheets
B6: INCOME SUMMARY
B7: ="Main Salary (YTD): RM "&TEXT('Salary Log'!C17,"#,##0.00") -> Main Salary (YTD): RM 51,600.00 | D7: ="Part-time Income (YTD): RM "&TEXT('Part-time Log'!E29,"#,##0.00") -> Part-time Income (YTD): RM 10,082.24 | F7: ="Total Income (YTD): RM "&TEXT('Salary Log'!C17+'Part-time Log'!E29,"#,##0.00") -> Total Income (YTD): RM 61,682.24
B9: ="EPF (YTD): RM "&TEXT('Salary Log'!D17,"#,##0.00") -> EPF (YTD): RM 5,676.00 | D9: ="SOCSO + EIS (YTD): RM "&TEXT('Salary Log'!E17+'Salary Log'!F17,"#,##0.00") -> SOCSO + EIS (YTD): RM 327.45 | F9: ="Net Salary (YTD): RM "&TEXT('Salary Log'!G17,"#,##0.00") -> Net Salary (YTD): RM 45,596.55
B12: TAX SUMMARY
B13: ="Total Reliefs: RM "&TEXT('Tax Engine'!D23,"#,##0.00") -> Total Reliefs: RM 9,979.35 | E13: ="Annual Tax (Est.): RM "&TEXT('Tax Engine'!D26,"#,##0.00") -> Annual Tax (Est.): RM 1,241.97
B15: ="PCB Paid (Jan-May): RM "&TEXT('Tax Engine'!D30,"#,##0.00") -> PCB Paid (Jan-May): RM 627.45 | E15: ="Total Due at e-Filing: RM "&TEXT('Tax Engine'!D34,"#,##0.00") -> Total Due at e-Filing: RM 614.52
B18: PURCHASES & CLAIMS SUMMARY
B19: Tax Relief Purchases Total | C19: =Purchases!L1 -> 746.1
B20: Work Expense Claims Total | C20: =Purchases!L2 -> 0
B21: Reimbursements Received | C21: =Purchases!L3 -> 0
B22: Outstanding Claims (not yet reimbursed) | C22: =Purchases!L4 -> 0
B25: HOW TO USE THIS FILE
B26: Step 1 → Salary Log | C26: Paste your Maybank CSV rows here each month. EPF/SOCSO/EIS auto-calculated.
B27: Step 2 → Part-time Log | C27: Paste Bank Islam CSV rows. File auto-detects 1st & 15th payments from Nuvera.
B28: Step 3 → Purchases | C28: Log every purchase here — tax relief items & Nuvera work claims with receipt details.
B29: Step 4 → File Links | C29: Paste links to your uploaded PDF payslips, bank statements, receipts here.
B30: Step 5 → Tax Engine | C30: Auto-calculates your full year tax. Do not edit — all formulas pull from other sheets.
B31: Step 6 → PCB Schedule | C31: Shows your monthly PCB paid vs estimated. Updates when you add salary data.

Sheet Salary Log
A1: SALARY LOG — MAIN SALARY (Maybank)
A2: Paste your Maybank CSV transaction rows into columns A–B (Date, Amount). Other columns auto-calculate. Blue cells = manual input.
A3: HOW TO EXPORT: Maybank2U → Accounts → Transaction History → Download CSV → Copy rows where description contains "salary" or "gaji" → Paste into row 5 onwards
A4: Month | B4: Date Received | C4: Gross Salary (RM) | D4: EPF 11% (RM) | E4: SOCSO (RM) | F4: EIS (RM) | G4: Net Salary (RM) | H4: PCB Deducted (RM) | I4: PCB Cumulative (RM) | J4: Payslip Ref | K4: Source | L4: Notes
A5: Jan | B5: 02/01/2026 | C5: 3100 | D5: =ROUND(C5*0.11,0) -> 341 | E5: =IF(C5<=4000,ROUND(C5*0.005,2),19.75) -> 15.5 | F5: =ROUND(MIN(C5,4000)*0.002,2) -> 6.2 | G5: =C5-D5-E5-F5 -> 2737.3 | H5: 0 | I5: =SUM(H5:H5) -> 0 | J5: Payslip_Jan_2026 | K5: Maybank CSV | L5: Confirmed
A6: Feb | B6: 01/02/2026 | C6: 4500 | D6: =ROUND(C6*0.11,0) -> 495 | E6: =IF(C6<=4000,ROUND(C6*0.005,2),19.75) -> 19.75 | F6: =ROUND(MIN(C6,4000)*0.002,2) -> 8 | G6: =C6-D6-E6-F6 -> 3977.25 | H6: 79.35 | I6: =SUM(H5:H6) -> 79.35 | J6: Payslip_Feb_2026 | K6: Maybank CSV | L6: Confirmed
A7: Mar | B7: 01/03/2026 | C7: 4500 | D7: =ROUND(C7*0.11,0) -> 495 | E7: =IF(C7<=4000,ROUND(C7*0.005,2),19.75) -> 19.75 | F7: =ROUND(MIN(C7,4000)*0.002,2) -> 8 | G7: =C7-D7-E7-F7 -> 3977.25 | H7: 79.2 | I7: =SUM(H5:H7) -> 158.55 | J7: Payslip_Mar_2026 | K7: Maybank CSV | L7: Confirmed
A8: Apr | B8: 01/04/2026 | C8: 4000 | D8: =ROUND(C8*0.11,0) -> 440 | E8: =IF(C8<=4000,ROUND(C8*0.005,2),19.75) -> 20 | F8: =ROUND(MIN(C8,4000)*0.002,2) -> 8 | G8: =C8-D8-E8-F8 -> 3532 | H8: 0 | I8: =SUM(H5:H8) -> 158.55 | J8: Payslip_Apr_2026 | K8: Maybank CSV | L8: Confirmed
A9: May | B9: 01/05/2026 | C9: 4500 | D9: =ROUND(C9*0.11,0) -> 495 | E9: =IF(C9<=4000,ROUND(C9*0.005,2),19.75) -> 19.75 | F9: =ROUND(MIN(C9,4000)*0.002,2) -> 8 | G9: =C9-D9-E9-F9 -> 3977.25 | H9: 468.9 | I9: =SUM(H5:H9) -> 627.45 | J9: Payslip_May_2026 | K9: Maybank CSV | L9: Confirmed
A10: Jun | B10: 01/06/2026 | C10: 4000 | D10: =ROUND(C10*0.11,0) -> 440 | E10: =IF(C10<=4000,ROUND(C10*0.005,2),19.75) -> 20 | F10: =ROUND(MIN(C10,4000)*0.002,2) -> 8 | G10: =C10-D10-E10-F10 -> 3532 | H10: 0 | I10: =SUM(H5:H10) -> 627.45 | J10: Payslip_Jun_2026 | K10: Maybank CSV | L10: Confirmed
A11: Jul | B11: 01/07/2026 | C11: 4500 | D11: =ROUND(C11*0.11,0) -> 495 | E11: =IF(C11<=4000,ROUND(C11*0.005,2),19.75) -> 19.75 | F11: =ROUND(MIN(C11,4000)*0.002,2) -> 8 | G11: =C11-D11-E11-F11 -> 3977.25 | H11: 0 | I11: =SUM(H5:H11) -> 627.45 | J11: Payslip_Jul_2026 | K11: Projected | L11: Update when received
A12: Aug | B12: 01/08/2026 | C12: 4500 | D12: =ROUND(C12*0.11,0) -> 495 | E12: =IF(C12<=4000,ROUND(C12*0.005,2),19.75) -> 19.75 | F12: =ROUND(MIN(C12,4000)*0.002,2) -> 8 | G12: =C12-D12-E12-F12 -> 3977.25 | H12: 0 | I12: =SUM(H5:H12) -> 627.45 | J12: Payslip_Aug_2026 | K12: Projected | L12: Update when received
A13: Sep | B13: 01/09/2026 | C13: 4500 | D13: =ROUND(C13*0.11,0) -> 495 | E13: =IF(C13<=4000,ROUND(C13*0.005,2),19.75) -> 19.75 | F13: =ROUND(MIN(C13,4000)*0.002,2) -> 8 | G13: =C13-D13-E13-F13 -> 3977.25 | H13: 0 | I13: =SUM(H5:H13) -> 627.45 | J13: Payslip_Sep_2026 | K13: Projected | L13: Update when received
A14: Oct | B14: 01/10/2026 | C14: 4500 | D14: =ROUND(C14*0.11,0) -> 495 | E14: =IF(C14<=4000,ROUND(C14*0.005,2),19.75) -> 19.75 | F14: =ROUND(MIN(C14,4000)*0.002,2) -> 8 | G14: =C14-D14-E14-F14 -> 3977.25 | H14: 0 | I14: =SUM(H5:H14) -> 627.45 | J14: Payslip_Oct_2026 | K14: Projected | L14: Update when received
A15: Nov | B15: 01/11/2026 | C15: 4500 | D15: =ROUND(C15*0.11,0) -> 495 | E15: =IF(C15<=4000,ROUND(C15*0.005,2),19.75) -> 19.75 | F15: =ROUND(MIN(C15,4000)*0.002,2) -> 8 | G15: =C15-D15-E15-F15 -> 3977.25 | H15: 0 | I15: =SUM(H5:H15) -> 627.45 | J15: Payslip_Nov_2026 | K15: Projected | L15: Update when received
A16: Dec | B16: 01/12/2026 | C16: 4500 | D16: =ROUND(C16*0.11,0) -> 495 | E16: =IF(C16<=4000,ROUND(C16*0.005,2),19.75) -> 19.75 | F16: =ROUND(MIN(C16,4000)*0.002,2) -> 8 | G16: =C16-D16-E16-F16 -> 3977.25 | H16: 0 | I16: =SUM(H5:H16) -> 627.45 | J16: Payslip_Dec_2026 | K16: Projected | L16: Update when received
A17: TOTAL / YTD | C17: =SUM(C5:C16) -> 51600 | D17: =SUM(D5:D16) -> 5676 | E17: =SUM(E5:E16) -> 233.25 | F17: =SUM(F5:F16) -> 94.2 | G17: =SUM(G5:G16) -> 45596.55 | H17: =SUM(H5:H16) -> 627.45 | I17: =H16 -> 0
A19: MAYBANK CSV FORMAT GUIDE
A20: Maybank CSV columns: | B20: Date | Description | Amount | Balance
A21: Filter for salary: | B21: Look for rows where Description contains "GAJI", "SALARY", or your company name
A22: Paste here: | B22: Copy the Date into column B, Amount into column C for each month
A23: Yellow cells: | B23: Cells highlighted in yellow = you need to update these manually
A24: PCB column H: | B24: Enter the PCB amount from your payslip each month into column H

Sheet Part-time Log
A1: PART-TIME INCOME LOG — NUVERA (Bank Islam)
A2: Payments received on 1st & 15th of each month. Paste Bank Islam CSV rows. Blue = manual input.
A3: HOW TO EXPORT: Bank Islam app → Account → Statement → Export CSV → Filter rows from USAMA or AHMAD ASHRAF → Paste Date into col B, Amount into col E
A4: Month | B4: Date | C4: From (Sender) | D4: Description / Reference | E4: Amount (RM) | F4: Payment Slot | G4: Type | H4: Reimbursement? | I4: Ref / Receipt No | J4: Notes
A5: Jan | B5: Jan 2026 | C5: Other account | D5: Part-time salary Jan | E5: 333.33 | F5: 1st | G5: Work | H5: No | I5: REF-JAN-01 | J5: Separate account
A6: Feb | B6: 01/02/2026 | C6: Ahmad Ashraf | D6: Elaun 1hb feb Programmer | E6: 100 | F6: 1st | G6: Work | H6: No | I6: REF-FEB-01
A7: Feb | B7: 02/02/2026 | C7: Ahmad Ashraf | D7: Elaun programmer Nuvera | E7: 900 | F7: 1st | G7: Work | H7: No | I7: REF-FEB-02
A8: Feb | B8: 15/02/2026 | C8: Usama bin Mazlin | D8: Elaun iskandar feb | E8: 1000 | F8: 15th | G8: Work | H8: No | I8: REF-FEB-15
A9: Mar | B9: 01/03/2026 | C9: Usama bin Mazlin | D9: Elaun iskandar feb | E9: 1000 | F9: 1st | G9: Work | H9: No | I9: REF-MAR-01
A10: Mar | B10: 16/03/2026 | C10: Usama bin Mazlin | D10: Elaun iskandar march | E10: 1110.8 | F10: 15th | G10: Work | H10: No | I10: REF-MAR-15
A11: Apr | B11: 01/04/2026 | C11: Usama bin Mazlin | D11: Gaji iskandar 1april | E11: 1000 | F11: 1st | G11: Work | H11: No | I11: REF-APR-01
A12: Apr | B12: 16/04/2026 | C12: Usama bin Mazlin | D12: Gaji april iskandar | E12: 1000 | F12: 15th | G12: Work | H12: No | I12: REF-APR-15
A13: May | B13: 02/05/2026 | C13: Ahmad Ashraf | D13: Elaun nuvera | E13: 1000 | F13: 1st | G13: Work | H13: No | I13: REF-MAY-01
A14: May | B14: 16/05/2026 | C14: Usama bin Mazlin | D14: May 15 salary | E14: 1000 | F14: 15th | G14: Work | H14: No | I14: REF-MAY-15
A15: Jun | B15: 01/06/2026 | C15: Usama bin Mazlin | D15: Gaji may 2026 | E15: 1638.11 | F15: 1st | G15: Work | H15: No | I15: REF-JUN-01
A16: Jul
A17: Jul
A18: Aug
A19: Aug
A20: Sep
A21: Sep
A22: Oct
A23: Oct
A24: Nov
A25: Nov
A26: Dec
A27: Dec
A29: TOTAL WORK INCOME | E29: =SUMIF(G5:G28,"Work",E5:E28) -> 10082.24
A31: MONTHLY SUMMARY — WORK INCOME ONLY
A32: Jan | B32: =SUMIFS(E5:E28,A5:A28,A32,G5:G28,"Work") -> 333.33 | C32: =COUNTIFS(A5:A28,A32,G5:G28,"Work") -> 1 | D32: payments
A33: Feb | B33: =SUMIFS(E5:E28,A5:A28,A33,G5:G28,"Work") -> 2000 | C33: =COUNTIFS(A5:A28,A33,G5:G28,"Work") -> 3 | D33: payments
A34: Mar | B34: =SUMIFS(E5:E28,A5:A28,A34,G5:G28,"Work") -> 2110.8 | C34: =COUNTIFS(A5:A28,A34,G5:G28,"Work") -> 2 | D34: payments
A35: Apr | B35: =SUMIFS(E5:E28,A5:A28,A35,G5:G28,"Work") -> 2000 | C35: =COUNTIFS(A5:A28,A35,G5:G28,"Work") -> 2 | D35: payments
A36: May | B36: =SUMIFS(E5:E28,A5:A28,A36,G5:G28,"Work") -> 2000 | C36: =COUNTIFS(A5:A28,A36,G5:G28,"Work") -> 2 | D36: payments
A37: Jun | B37: =SUMIFS(E5:E28,A5:A28,A37,G5:G28,"Work") -> 1638.11 | C37: =COUNTIFS(A5:A28,A37,G5:G28,"Work") -> 1 | D37: payments
A38: Jul | B38: =SUMIFS(E5:E28,A5:A28,A38,G5:G28,"Work") -> 0 | C38: =COUNTIFS(A5:A28,A38,G5:G28,"Work") -> 0 | D38: payments
A39: Aug | B39: =SUMIFS(E5:E28,A5:A28,A39,G5:G28,"Work") -> 0 | C39: =COUNTIFS(A5:A28,A39,G5:G28,"Work") -> 0 | D39: payments
A40: Sep | B40: =SUMIFS(E5:E28,A5:A28,A40,G5:G28,"Work") -> 0 | C40: =COUNTIFS(A5:A28,A40,G5:G28,"Work") -> 0 | D40: payments
A41: Oct | B41: =SUMIFS(E5:E28,A5:A28,A41,G5:G28,"Work") -> 0 | C41: =COUNTIFS(A5:A28,A41,G5:G28,"Work") -> 0 | D41: payments
A42: Nov | B42: =SUMIFS(E5:E28,A5:A28,A42,G5:G28,"Work") -> 0 | C42: =COUNTIFS(A5:A28,A42,G5:G28,"Work") -> 0 | D42: payments
...

Sheet Purchases
A1: PURCHASES & CLAIMS TRACKER — TAX RELIEF + NUVERA WORK EXPENSES | K1: Tax Relief Total | L1: =SUMIF(D7:D200,"Tax Relief",F7:F200) -> 746.1
A2: Log EVERY purchase here. Tax relief items reduce your tax. Work claims get reimbursed by boss. | K2: Work Claims Total | L2: =SUMIF(D7:D200,"Work Claim",F7:F200) -> 0
K3: Reimbursed Total | L3: =SUMIF(H7:H200,"Reimbursed",F7:F200) -> 0
K4: Outstanding Claims | L4: =SUMIF(H7:H200,"Pending",F7:F200) -> 0
A6: Date | B6: Month | C6: Item Description | D6: Type | E6: Relief Category | F6: Amount (RM) | G6: Receipt No. | H6: Status | I6: File Link / Path | J6: Relief Limit (RM) | K6: Notes | L6: Claimable?
A7: 01/01/2026 | B7: Jan | C7: WiFi Bill (Unifi) | D7: Tax Relief | E7: Lifestyle-WiFi | F7: 94.35 | G7: RCPT-WIFI-JAN | H7: Claimed | J7: 2500 | K7: Monthly bill | L7: Yes
A8: 01/02/2026 | B8: Feb | C8: WiFi Bill (Unifi) | D8: Tax Relief | E8: Lifestyle-WiFi | F8: 94.35 | G8: RCPT-WIFI-FEB | H8: Claimed | J8: 2500 | K8: Monthly bill | L8: Yes
A9: 01/03/2026 | B9: Mar | C9: WiFi Bill (Unifi) | D9: Tax Relief | E9: Lifestyle-WiFi | F9: 94.35 | G9: RCPT-WIFI-MAR | H9: Claimed | J9: 2500 | K9: Monthly bill | L9: Yes
A10: 01/04/2026 | B10: Apr | C10: WiFi Bill (Unifi) | D10: Tax Relief | E10: Lifestyle-WiFi | F10: 94.35 | G10: RCPT-WIFI-APR | H10: Claimed | J10: 2500 | K10: Monthly bill | L10: Yes
A11: 01/05/2026 | B11: May | C11: WiFi Bill (Unifi) | D11: Tax Relief | E11: Lifestyle-WiFi | F11: 94.35 | G11: RCPT-WIFI-MAY | H11: Claimed | J11: 2500 | K11: Monthly bill | L11: Yes
A12: 01/06/2026 | B12: Jun | C12: WiFi Bill (Unifi) | D12: Tax Relief | E12: Lifestyle-WiFi | F12: 94.35 | G12: RCPT-WIFI-JUN | H12: Claimed | J12: 2500 | K12: Monthly bill | L12: Yes
A13: Jan 2026 | B13: Jan | C13: Life Insurance Premium | D13: Tax Relief | E13: Life Insurance | F13: 30 | G13: RCPT-INS-JAN | H13: Claimed | J13: 3000 | K13: Monthly premium | L13: Yes
A14: Feb 2026 | B14: Feb | C14: Life Insurance Premium | D14: Tax Relief | E14: Life Insurance | F14: 30 | G14: RCPT-INS-FEB | H14: Claimed | J14: 3000 | K14: Monthly premium | L14: Yes
A15: Mar 2026 | B15: Mar | C15: Life Insurance Premium | D15: Tax Relief | E15: Life Insurance | F15: 30 | G15: RCPT-INS-MAR | H15: Claimed | J15: 3000 | K15: Monthly premium | L15: Yes
A16: Apr 2026 | B16: Apr | C16: Life Insurance Premium | D16: Tax Relief | E16: Life Insurance | F16: 30 | G16: RCPT-INS-APR | H16: Claimed | J16: 3000 | K16: Monthly premium | L16: Yes
A17: May 2026 | B17: May | C17: Life Insurance Premium | D17: Tax Relief | E17: Life Insurance | F17: 30 | G17: RCPT-INS-MAY | H17: Claimed | J17: 3000 | K17: Monthly premium | L17: Yes
A18: Jun 2026 | B18: Jun | C18: Life Insurance Premium | D18: Tax Relief | E18: Life Insurance | F18: 30 | G18: RCPT-INS-JUN | H18: Claimed | J18: 3000 | K18: Monthly premium | L18: Yes
A41: RELIEF CATEGORY SUMMARY — AUTO-UPDATED
A42: Category | B42: Annual Limit (RM) | C42: Claimed So Far (RM) | D42: Remaining Room (RM) | E42: % Used
A43: Life Insurance | B43: 3000 | C43: =SUMIFS(F5:F37,E5:E37,A43,D5:D37,"Tax Relief") -> 180 | D43: =MAX(0,B43-C43) -> 2820 | E43: =IF(B43>0,MIN(C43/B43,1),0) -> 0.06
A44: Medical Insurance | B44: 4000 | C44: =SUMIFS(F5:F37,E5:E37,A44,D5:D37,"Tax Relief") -> 0 | D44: =MAX(0,B44-C44) -> 4000 | E44: =IF(B44>0,MIN(C44/B44,1),0) -> 0
A45: Lifestyle-WiFi | B45: 2500 | C45: =SUMIFS(F5:F37,E5:E37,A45,D5:D37,"Tax Relief") -> 566.1 | D45: =MAX(0,B45-C45) -> 1933.9 | E45: =IF(B45>0,MIN(C45/B45,1),0) -> 0.22644
A46: Lifestyle-Phone/Book/Gadget | B46: 2500 | C46: =SUMIFS(F5:F37,E5:E37,A46,D5:D37,"Tax Relief") -> 0 | D46: =MAX(0,B46-C46) -> 2500 | E46: =IF(B46>0,MIN(C46/B46,1),0) -> 0
A47: Lifestyle-Sports/Gym | B47: 1000 | C47: =SUMIFS(F5:F37,E5:E37,A47,D5:D37,"Tax Relief") -> 0 | D47: =MAX(0,B47-C47) -> 1000 | E47: =IF(B47>0,MIN(C47/B47,1),0) -> 0
A48: Medical/Dental/Checkup | B48: 1000 | C48: =SUMIFS(F5:F37,E5:E37,A48,D5:D37,"Tax Relief") -> 0 | D48: =MAX(0,B48-C48) -> 1000 | E48: =IF(B48>0,MIN(C48/B48,1),0) -> 0
A49: SOCSO | B49: 350 | C49: =SUMIFS(F5:F37,E5:E37,A49,D5:D37,"Tax Relief") -> 0 | D49: =MAX(0,B49-C49) -> 350 | E49: =IF(B49>0,MIN(C49/B49,1),0) -> 0
A50: SSPN | B50: 8000 | C50: =SUMIFS(F5:F37,E5:E37,A50,D5:D37,"Tax Relief") -> 0 | D50: =MAX(0,B50-C50) -> 8000 | E50: =IF(B50>0,MIN(C50/B50,1),0) -> 0
A51: PRS | B51: 3000 | C51: =SUMIFS(F5:F37,E5:E37,A51,D5:D37,"Tax Relief") -> 0 | D51: =MAX(0,B51-C51) -> 3000 | E51: =IF(B51>0,MIN(C51/B51,1),0) -> 0
A52: Skills Course | B52: 7000 | C52: =SUMIFS(F5:F37,E5:E37,A52,D5:D37,"Tax Relief") -> 0 | D52: =MAX(0,B52-C52) -> 7000 | E52: =IF(B52>0,MIN(C52/B52,1),0) -> 0

Sheet File Links
A1: FILE LINKS — PAYSLIPS, BANK STATEMENTS & RECEIPTS
A2: Upload your files to Google Drive / OneDrive / any cloud storage → paste the share link into column F
A3: TIP: Google Drive → Right-click file → Share → Copy link → Paste in column F. Or use OneDrive / Dropbox. Keep files organised in folders by month.
A4: Month | B4: Year | C4: Document Type | D4: File Name / Description | E4: File Format | F4: Link / Path | G4: Upload Status
A5: Jan | B5: 2026 | C5: Payslip | D5: Payslip_Jan_2026 — Main Salary (Maybank) | E5: PDF | F5: Paste link here | G5: Pending
A6: Jan | B6: 2026 | C6: Bank Statement | D6: Bank_Islam_Statement_Jan_2026 — Part-time | E6: CSV/PDF | F6: Paste link here | G6: Pending
A7: Feb | B7: 2026 | C7: Payslip | D7: Payslip_Feb_2026 — Main Salary (Maybank) | E7: PDF | F7: Paste link here | G7: Pending
A8: Feb | B8: 2026 | C8: Bank Statement | D8: Bank_Islam_Statement_Feb_2026 — Part-time | E8: CSV/PDF | F8: Paste link here | G8: Pending
A9: Mar | B9: 2026 | C9: Payslip | D9: Payslip_Mar_2026 — Main Salary (Maybank) | E9: PDF | F9: Paste link here | G9: Pending
A10: Mar | B10: 2026 | C10: Bank Statement | D10: Bank_Islam_Statement_Mar_2026 — Part-time | E10: CSV/PDF | F10: Paste link here | G10: Pending
A11: Apr | B11: 2026 | C11: Payslip | D11: Payslip_Apr_2026 — Main Salary (Maybank) | E11: PDF | F11: Paste link here | G11: Pending
A12: Apr | B12: 2026 | C12: Bank Statement | D12: Bank_Islam_Statement_Apr_2026 — Part-time | E12: CSV/PDF | F12: Paste link here | G12: Pending
A13: May | B13: 2026 | C13: Payslip | D13: Payslip_May_2026 — Main Salary (Maybank) | E13: PDF | F13: Paste link here | G13: Pending
A14: May | B14: 2026 | C14: Bank Statement | D14: Bank_Islam_Statement_May_2026 — Part-time | E14: CSV/PDF | F14: Paste link here | G14: Pending
A15: Jun | B15: 2026 | C15: Payslip | D15: Payslip_Jun_2026 — Main Salary (Maybank) | E15: PDF | F15: Paste link here | G15: Pending
... A32: ALL | B32: 2026 | C32: Tax Document | D32: MyTax PCB Statement 2026 | E32: PDF | F32: Paste link here | G32: Pending

Sheet Tax Engine
A1: TAX ENGINE — AUTO CALCULATION (DO NOT EDIT)
A2: All values pull automatically from Salary Log, Part-time Log and Purchases sheets.
A3: Description | C3: Main Salary Only | D3: With Part-time | E3: Difference
A4: INCOME
A5: Total Gross Main Salary | C5: =SUM('Salary Log'!C5:C16) -> 51600 | D5: =SUM('Salary Log'!C5:C16) -> 51600 | E5: =D5-C5 -> 0
A6: Part-time Income (Work) | C6: =0 -> 0 | D6: =SUMIF('Part-time Log'!G5:G39,"Work",'Part-time Log'!E5:E39) -> 10082.24 | E6: =D6-C6 -> 10082.24
A7: Total Gross Income | C7: =C5+C6 -> 51600 | D7: =D5+D6 -> 61682.24 | E7: =D7-C7 -> 10082.24
A8: DEDUCTIONS (Main Salary)
A9: EPF 11% | C9: =SUM('Salary Log'!D5:D16) -> 5676 | D9: =SUM('Salary Log'!D5:D16) -> 5676 | E9: =D9-C9 -> 0
A10: SOCSO | C10: =SUM('Salary Log'!E5:E16) -> 233.25 | D10: =SUM('Salary Log'!E5:E16) -> 233.25 | E10: =D10-C10 -> 0
A11: EIS | C11: =SUM('Salary Log'!F5:F16) -> 94.2 | D11: =SUM('Salary Log'!F5:F16) -> 94.2 | E11: =D11-C11 -> 0
A12: Total Deductions | C12: =C9+C10+C11 -> 6003.45 | D12: =D9+D10+D11 -> 6003.45 | E12: =D12-C12 -> 0
A13: Net Income | C13: =C7-C12 -> 45596.55 | D13: =D7-D12 -> 55678.79 | E13: =D13-C13 -> 10082.24
A14: RELIEFS
A15: Personal Relief | C15: =9000 -> 9000 | D15: =9000 -> 9000 | E15: =D15-C15 -> 0
A16: Life Insurance | C16: =SUMIF(Purchases!E5:E500,"Life Insurance",Purchases!F5:F500) -> 180 | D16: =SUMIF(Purchases!E5:E500,"Life Insurance",Purchases!F5:F500) -> 180 | E16: =D16-C16 -> 0
A17: Lifestyle (WiFi+Phone+Books+Sports) | C17: =MIN(SUMIF(Purchases!E5:E500,"Lifestyle-WiFi",Purchases!F5:F500)+SUMIF(Purchases!E5:E500,"Lifestyle-Phone/Book/Gadget",Purchases!F5:F500)+SUMIF(Purchases!E5:E500,"Lifestyle-Sports/Gym",Purchases!F5:F500),2500) -> 566.1 | D17: =MIN(SUMIF(Purchases!E5:E500,"Lifestyle-WiFi",Purchases!F5:F500)+SUMIF(Purchases!E5:E500,"Lifestyle-Phone/Book/Gadget",Purchases!F5:F500)+SUMIF(Purchases!E5:E500,"Lifestyle-Sports/Gym",Purchases!F5:F500),2500) -> 566.1 | E17: =D17-C17 -> 0
A18: SOCSO Contribution | C18: =MIN(SUM('Salary Log'!E5:E16),350) -> 233.25 | D18: =MIN(SUM('Salary Log'!E5:E16),350) -> 233.25 | E18: =D18-C18 -> 0
A19: Medical/Dental | C19: =MIN(SUMIF(Purchases!E5:E500,"Medical/Dental/Checkup",Purchases!F5:F500),1000) -> 0 | D19: =MIN(SUMIF(Purchases!E5:E500,"Medical/Dental/Checkup",Purchases!F5:F500),1000) -> 0 | E19: =D19-C19 -> 0
A20: SSPN | C20: =MIN(SUMIF(Purchases!E5:E500,"SSPN",Purchases!F5:F500),8000) -> 0 | D20: =MIN(SUMIF(Purchases!E5:E500,"SSPN",Purchases!F5:F500),8000) -> 0 | E20: =D20-C20 -> 0
A21: PRS | C21: =MIN(SUMIF(Purchases!E5:E500,"PRS",Purchases!F5:F500),3000) -> 0 | D21: =MIN(SUMIF(Purchases!E5:E500,"PRS",Purchases!F5:F500),3000) -> 0 | E21: =D21-C21 -> 0
A22: Skills Course | C22: =MIN(SUMIF(Purchases!E5:E500,"Skills Course",Purchases!F5:F500),7000) -> 0 | D22: =MIN(SUMIF(Purchases!E5:E500,"Skills Course",Purchases!F5:F500),7000) -> 0 | E22: =D22-C22 -> 0
A23: TOTAL RELIEFS | C23: =SUM(C15:C22) -> 9979.35 | D23: =SUM(D15:D22) -> 9979.35 | E23: =D23-C23 -> 0
A24: CHARGEABLE INCOME & TAX
A25: Chargeable Income | C25: =MAX(0,C13-C23) -> 35617.2 | D25: =MAX(0,D13-D23) -> 45699.44 | E25: =D25-C25 -> 10082.24
A26: Annual Tax | C26: =IF(C25<=5000,0,IF(C25<=20000,(C25-5000)*0.01,IF(C25<=35000,150+(C25-20000)*0.03,IF(C25<=50000,600+(C25-35000)*0.06,IF(C25<=70000,1500+(C25-50000)*0.11,IF(C25<=100000,3700+(C25-70000)*0.19,9400+(C25-100000)*0.25)))))) -> 637.032 | D26: =IF(D25<=5000,0,IF(D25<=20000,(D25-5000)*0.01,IF(D25<=35000,150+(D25-20000)*0.03,IF(D25<=50000,600+(D25-35000)*0.06,IF(D25<=70000,1500+(D25-50000)*0.11,IF(D25<=100000,3700+(D25-70000)*0.19,9400+(D25-100000)*0.25)))))) -> 1241.9664 | E26: =D26-C26 -> 604.9344
A27: Effective Tax Rate | C27: =IF(C7>0,C26/C7,0) -> 0.012345581 | D27: =IF(D7>0,D26/D7,0) -> 0.020134911 | E27: =D27-C27 -> 0.0077893294
A28: Extra Tax (Part-time) | C28: =0 -> 0 | D28: =MAX(0,D26-C26) -> 604.9344 | E28: =D28-C28 -> 604.9344
A29: PCB & PAYMENT
A30: PCB Paid Jan–May | C30: =SUM('Salary Log'!H5:H9) -> 627.45 | D30: =SUM('Salary Log'!H5:H9) -> 627.45 | E30: =D30-C30 -> 0
A31: PCB Remaining (Jun–Dec) | C31: =MAX(0,C26-C30) -> 9.582 | D31: =MAX(0,C26-C30) -> 9.582 | E31: =D31-C31 -> 0
A32: PCB per month (Jun–Dec) | C32: =C31/7 -> 1.3688571 | D32: =D31/7 -> 1.3688571 | E32: =D32-C32 -> 0
A33: Part-time tax at e-Filing | C33: =0 -> 0 | D33: =D28 -> 604.9344 | E33: =D33-C33 -> 604.9344
A34: TOTAL DUE AT e-FILING | C34: =C31+C33 -> 9.582 | D34: =D31+D33 -> 614.5164 | E34: =D34-C34 -> 604.9344
A35: Set aside per month | C35: =C33/7 -> 0 | D35: =D33/7 -> 86.4192 | E35: =D35-C35 -> 86.4192
A37: ⚠ DO NOT EDIT THIS SHEET — All cells are formula-driven. Add data in Salary Log, Part-time Log, and Purchases only.

Sheet PCB Schedule
A1: PCB MONTHLY SCHEDULE — 2026
A2: Actual paid (Jan–May confirmed) vs estimated remaining (Jun–Dec). Updates automatically.
A3: Month | B3: Gross Salary | C3: Part-time | D3: PCB Actual (RM) | E3: PCB Est. (RM) | F3: Cumulative (RM) | G3: Main Tax YTD | H3: Status | I3: Notes
A4: Jan | B4: ='Salary Log'!C5 -> 3100 | C4: =SUMIFS('Part-time Log'!E5:E39,'Part-time Log'!A5:A39,A4,'Part-time Log'!G5:G39,"Work") -> 333.33 | D4: 0 | E4: 0 | F4: =SUM(E4:E4) -> 0 | G4: =SUM(D4:D4) -> 0 | H4: Paid | I4: Confirmed via MyTax
A5: Feb | B5: ='Salary Log'!C6 -> 4500 | C5: =SUMIFS('Part-time Log'!E5:E39,'Part-time Log'!A5:A39,A5,'Part-time Log'!G5:G39,"Work") -> 2000 | D5: 79.35 | E5: 79.35 | F5: =SUM(E4:E5) -> 79.35 | G5: =SUM(D4:D5) -> 79.35 | H5: Paid | I5: Confirmed via MyTax
A6: Mar | B6: ='Salary Log'!C7 -> 4500 | C6: =SUMIFS('Part-time Log'!E5:E39,'Part-time Log'!A5:A39,A6,'Part-time Log'!G5:G39,"Work") -> 2110.8 | D6: 79.2 | E6: 79.2 | F6: =SUM(E4:E6) -> 158.55 | G6: =SUM(D4:D6) -> 158.55 | H6: Paid | I6: Confirmed via MyTax
A7: Apr | B7: ='Salary Log'!C8 -> 4000 | C7: =SUMIFS('Part-time Log'!E5:E39,'Part-time Log'!A5:A39,A7,'Part-time Log'!G5:G39,"Work") -> 2000 | D7: 0 | E7: 0 | F7: =SUM(E4:E7) -> 158.55 | G7: =SUM(D4:D7) -> 158.55 | H7: Paid | I7: Confirmed via MyTax
A8: May | B8: ='Salary Log'!C9 -> 4500 | C8: =SUMIFS('Part-time Log'!E5:E39,'Part-time Log'!A5:A39,A8,'Part-time Log'!G5:G39,"Work") -> 2000 | D8: 468.9 | E8: 468.9 | F8: =SUM(E4:E8) -> 627.45 | G8: =SUM(D4:D8) -> 627.45 | H8: Paid | I8: Confirmed via MyTax
A9: Jun | B9: ='Salary Log'!C10 -> 4000 | C9: =SUMIFS('Part-time Log'!E5:E39,'Part-time Log'!A5:A39,A9,'Part-time Log'!G5:G39,"Work") -> 1638.11 | D9: 0 | E9: ='Tax Engine'!D32 -> 1.3688571 | F9: =SUM(E4:E9) -> 628.81886 | G9: =SUM(D4:D9) -> 627.45 | H9: Next → | I9: Update when paid
A10: Jul | B10: ='Salary Log'!C11 -> 4500 | C10: =SUMIFS('Part-time Log'!E5:E39,'Part-time Log'!A5:A39,A10,'Part-time Log'!G5:G39,"Work") -> 0 | D10: 0 | E10: ='Tax Engine'!D32 -> 1.3688571 | F10: =SUM(E4:E10) -> 630.18771 | G10: =SUM(D4:D10) -> 627.45 | H10: Upcoming | I10: Projected
A11: Aug | B11: ='Salary Log'!C12 -> 4500 | C11: =SUMIFS('Part-time Log'!E5:E39,'Part-time Log'!A5:A39,A11,'Part-time Log'!G5:G39,"Work") -> 0 | D11: 0 | E11: ='Tax Engine'!D32 -> 1.3688571 | F11: =SUM(E4:E11) -> 631.55657 | G11: =SUM(D4:D11) -> 627.45 | H11: Upcoming | I11: Projected
A12: Sep | B12: ='Salary Log'!C13 -> 4500 | C12: =SUMIFS('Part-time Log'!E5:E39,'Part-time Log'!A5:A39,A12,'Part-time Log'!G5:G39,"Work") -> 0 | D12: 0 | E12: ='Tax Engine'!D32 -> 1.3688571 | F12: =SUM(E4:E12) -> 632.92543 | G12: =SUM(D4:D12) -> 627.45 | H12: Upcoming | I12: Projected
A13: Oct | B13: ='Salary Log'!C14 -> 4500 | C13: =SUMIFS('Part-time Log'!E5:E39,'Part-time Log'!A5:A39,A13,'Part-time Log'!G5:G39,"Work") -> 0 | D13: 0 | E13: ='Tax Engine'!D32 -> 1.3688571 | F13: =SUM(E4:E13) -> 634.29429 | G13: =SUM(D4:D13) -> 627.45 | H13: Upcoming | I13: Projected
A14: Nov | B14: ='Salary Log'!C15 -> 4500 | C14: =SUMIFS('Part-time Log'!E5:E39,'Part-time Log'!A5:A39,A14,'Part-time Log'!G5:G39,"Work") -> 0 | D14: 0 | E14: ='Tax Engine'!D32 -> 1.3688571 | F14: =SUM(E4:E14) -> 635.66314 | G14: =SUM(D4:D14) -> 627.45 | H14: Upcoming | I14: Projected
A15: Dec | B15: ='Salary Log'!C16 -> 4500 | C15: =SUMIFS('Part-time Log'!E5:E39,'Part-time Log'!A5:A39,A15,'Part-time Log'!G5:G39,"Work") -> 0 | D15: 0 | E15: ='Tax Engine'!D32 -> 1.3688571 | F15: =SUM(E4:E15) -> 637.032 | G15: =SUM(D4:D15) -> 627.45 | H15: Upcoming | I15: Projected
A16: TOTAL | C16: =SUM(B4:B15) -> 51600 | D16: =SUM(C4:C15) -> 10082.24 | E16: =SUM(D4:D15) -> 627.45 | F16: =SUM(E4:E15) -> 637.032 | G16: =E15 -> 1.3688571 | H16: =D15 -> 0

Sheet e-Filing Guide (BE)
A1: e-FILING GUIDE — BORANG BE 2026 | Deadline: 30 April 2027 | mytax.hasil.gov.my
A2: Based on your actual Borang BE 2025 form. Yellow = enter this value. Green = auto-calculated by LHDN.
A3: Field (Borang BE) | B3: Description / What to Enter | C3: Your Value (RM) | D3: Where to Find / Tip
A4: STEP 1 — BEFORE YOU START
A5: Login to MyTax | B5: Go to mytax.hasil.gov.my → Login with MyTax ID or IC number (011209030803) | C5: mytax.hasil.gov.my | D5: Use Chrome or Edge. Avoid mobile browser for filing.
A6: Select e-BE form | B6: Dashboard → e-Filing → e-BE → Year 2026 (NOT 2025) | C6: Select 2026 | D6: ⚠ Make sure year is 2026 — easy mistake to select wrong year
A7: Check pre-filled data | B7: LHDN pre-fills salary from PCB records. Verify it matches your payslips. | C7: Check vs Salary Log | D7: If LHDN figure differs from yours, use YOUR correct figure
A8: Have these ready | B8: Payslips (all 12), Bank Islam statement, insurance cert, WiFi bills, phone receipt | C8: See File Links sheet | D8: Keep receipts 7 years — LHDN can audit anytime
A9: BAHAGIAN A — MAKLUMAT INDIVIDU (Personal Information)
A10: Nama / IC | B10: IESKANDAR ZULQARNAIN BIN GHAZALI | IC: 011209030803 | C10: Pre-filled by LHDN | D10: Verify spelling is correct
A11: Status Perkahwinan | B11: BUJANG — single, no spouse claiming relief | C11: Bujang | D11: Your 2025 form confirms this status
A12: Kategori | B12: Pemastautin (Resident) — you are Malaysian resident | C12: Pemastautin | D12: Correct — you qualify for all resident reliefs
A13: BAHAGIAN B — PENDAPATAN (Income)
A14: B1 — Penggajian (Gaji Pokok) | B14: Enter TOTAL employment income: main salary PLUS part-time income combined. Both count as "penggajian". | C14: ='Tax Engine'!D7 -> 61682.24 | D14: Main + part-time gross combined. Do NOT separate into different fields.
A15: B1a — Elaun/Perkuisit | B15: Allowances paid by employer. If your RM500 allowance is included in gross already, leave 0. | C15: 0 | D15: Check payslip — if allowance already in B1 gross figure, do not double-count
A16: B5 — Pendapatan Agregat | B16: LHDN auto-calculates total income. Just verify the number. | C16: Auto by LHDN | D16: Should equal your B1 + any other income
A17: B6 — Caruman KWSP | B17: Total EPF deducted from main salary ALL 12 months. Part-time has no EPF. | C17: ='Tax Engine'!C9 -> 5676 | D17: From Salary Log — sum of column D. DO NOT include part-time EPF (none deducted)
A18: B7 — Pendapatan Berkanun | B18: Statutory income = B5 minus B6 (EPF). LHDN auto-calculates. | C18: Auto by LHDN | D18: Verify = Tax Engine D13
A19: BAHAGIAN C — PELEPASAN CUKAI (Tax Reliefs) — From your actual 2025 Borang BE fields
A20: Individu dan saudara tanggungan | B20: Personal relief RM9,000. Pre-filled automatically. Do NOT change. | C20: 9,000.00 | D20: Auto-filled. Just verify it shows RM9,000.
A21: Perbelanjaan ibu bapa — Rawatan perubatan, pergigian, penjaga | B21: Medical expenses for parents. Leave 0 — you have no dependent parents claimed. | C21: 0 | D21: Only claim if you paid for parents' medical bills
A22: Perbelanjaan ibu bapa — Pemeriksaan perubatan penuh + pemvaksinan (Terhad RM1,000) | B22: Full medical checkup for parents. Leave 0 unless you paid for parents. | C22: 0 | D22: JUMLAH for parents capped at RM8,000 total
A23: Yuran pengajian (Sendiri) — Kursus kemahiran (Terhad RM2,000) | B23: Skills/upskilling courses you paid for yourself (Udemy, certs, etc). Under RM7,000 total limit. | C23: =MIN(SUMIF(Purchases!E7:E200,"Skills Course",Purchases!F7:F200),2000) -> 0 | D23: From Purchases sheet — Skills Course category. Limit RM7,000 total for all yuran pengajian.
A24: Perbelanjaan perubatan — Penyakit serius (diri/pasangan/anak) | B24: Serious illness treatment costs. Leave 0 unless you had serious illness treatment. | C24: 0 | D24: JUMLAH for all medical expenses capped at RM10,000
A25: Perbelanjaan perubatan — Pemvaksinan (diri/pasangan/anak, Terhad RM1,000) | B25: Vaccination costs for yourself. Claim if you got any vaccines in 2026. | C25: =MIN(SUMIF(Purchases!E7:E200,"Medical/Dental/Checkup",Purchases!F7:F200)*0.3,1000) -> 0 | D25: Estimate — update if you have separate vaccination receipts. Limit RM1,000.
A26: Perbelanjaan perubatan — Pergigian (diri/pasangan/anak, Terhad RM1,000) | B26: Dental treatment costs for yourself. Claim any dental visits in 2026. | C26: =MIN(SUMIF(Purchases!E7:E200,"Medical/Dental/Checkup",Purchases!F7:F200)*0.7,1000) -> 0 | D26: Estimate — update with actual dental receipt amount. Limit RM1,000.
A27: Perbelanjaan perubatan — Pemeriksaan perubatan penuh / ujian / kesihatan mental (Terhad RM1,000) | B27: Full medical checkup, disease detection tests, mental health consultation for yourself. | C27: =MIN(SUMIF(Purchases!E7:E200,"Medical/Dental/Checkup",Purchases!F7:F200),1000) -> 0 | D27: From Purchases sheet. Includes checkup + self-test equipment. Limit RM1,000.
A28: Gaya hidup — Terhad RM2,500 | B28: WiFi bills + phone/gadget purchase + books + sports equipment + gym fees. SHARED RM2,500 limit. | C28: =MIN(SUMIF(Purchases!E7:E200,"Lifestyle-WiFi",Purchases!F7:F200)+SUMIF(Purchases!E7:E200,"Lifestyle-Phone/Book/Gadget",Purchases!F7:F200)+SUMIF(Purchases!E7:E200,"Lifestyle-Sports/Gym",Purchases!F7:F200),2500) -> 566.1 | D28: Your WiFi RM1,132 + Phone claim RM1,368 = RM2,500 MAXED. Includes books, gadgets, gym under same limit.
A29: Gaya hidup tambahan — Sukan (Terhad RM1,000) | B29: ADDITIONAL sports relief — gym membership, sports equipment, competition entry fees. | C29: =MIN(SUMIF(Purchases!E7:E200,"Lifestyle-Sports/Gym",Purchases!F7:F200),1000) -> 0 | D29: This is SEPARATE from the RM2,500 lifestyle limit above. Sports gets an extra RM1,000 on top!
A30: Tabungan bersih SSPN (Terhad RM8,000) | B30: Net savings deposited into SSPN Prima account in 2026. Open account at sspn.com.my | C30: =MIN(SUMIF(Purchases!E7:E200,"SSPN",Purchases!F7:F200),8000) -> 0 | D30: Currently RM0 — consider opening SSPN to claim up to RM8,000 relief. High impact!
A31: Insurans nyawa + KWSP Sukarela (Terhad RM3,000 insurans, RM4,000 KWSP) | B31: Life insurance premiums (RM30/month) + any voluntary EPF top-up. JUMLAH limit RM7,000. | C31: =MIN(SUMIF(Purchases!E7:E200,"Life Insurance",Purchases!F7:F200),3000) -> 180 | D31: Your RM360/year life insurance. Voluntary EPF (i-Saraan) also goes here if applicable.
A32: Skim persaraan swasta / PRS (Terhad RM3,000) | B32: Contributions to Private Retirement Scheme (PRS) funds — Public Mutual, Kenanga, etc. | C32: =MIN(SUMIF(Purchases!E7:E200,"PRS",Purchases!F7:F200),3000) -> 0 | D32: Currently RM0 — consider PRS to save RM90–150 in tax + build retirement fund.
A33: Insurans pendidikan dan perubatan (Terhad RM4,000) | B33: Medical card or education insurance premiums. SEPARATE limit from life insurance above. | C33: =MIN(SUMIF(Purchases!E7:E200,"Medical Insurance",Purchases!F7:F200),4000) -> 0 | D33: Currently RM0 — upgrading insurance to include medical card gives RM4,000 extra relief!
A34: Caruman PERKESO/SOCSO (Terhad RM350) | B34: Total SOCSO + EIS deducted from your main salary payslips. Already paid — just claim it. | C34: =MIN(SUM('Salary Log'!E5:E16)+SUM('Salary Log'!F5:F16),350) -> 327.45 | D34: Your 2025 form shows RM181 — 2026 will be similar ~RM237. Check your payslips.
A35: Faedah pinjaman rumah pertama | B35: Interest paid on first home loan. Leave 0 — you have no home loan. | C35: 0 | D35: Only applicable if you own a house with a mortgage
A36: REBAT / TOLAKAN CUKAI (Rebates & Tax Deductions)
A37: Zakat dan Fitrah | B37: If you paid zakat or fitrah in 2026, enter total amount here. Acts as direct tax rebate. | C37: 0 | D37: Enter actual zakat paid — reduces your tax RM for RM (not just relief). Very powerful!
A38: Levi Umrah (Terhad 2 kali seumur hidup) | B38: Levy paid for umrah trip or religious pilgrimage. Terhad 2 kali seumur hidup. | C38: 0 | D38: Only if you went for umrah in 2026
A39: Tolakan cukai Seksyen 110 | B39: Foreign tax credit. Leave 0 — only if you paid tax overseas. | C39: 0 | D39: Not applicable for your situation
A40: BAHAGIAN D — CUKAI & BAYARAN (Tax Calculation & Payment)
...

Sheet My BE Form Values
A1: MY BORANG BE 2026 — ACTUAL FIELD VALUES | Print and refer when filing at mytax.hasil.gov.my
A2: Values auto-calculated from your tracker. Update Salary Log & Purchases first for accuracy.
A3: IMPORTANT: Your 2025 Borang BE balance was RM52.43. For 2026, the balance will be higher if you declare part-time income from Nuvera. All values below are estimates — verify against MyTax ledger before submitting.
A4: Borang BE Field (Exact Label) | B4: Your Value (RM) | C4: Limit / Notes | D4: Status
A5: BAHAGIAN B — PENDAPATAN (Income)
A6: B1 — Penggajian (Main + Part-time combined) | B6: ='Tax Engine'!D7 -> 61682.24 | C6: Include BOTH main salary and Nuvera income here | D6: Mandatory
A7: B6 — Caruman KWSP (EPF main salary only) | B7: ='Tax Engine'!C9 -> 5676 | C7: EPF from main salary only — part-time has no EPF | D7: Mandatory
A8: B7 — Pendapatan Berkanun (Statutory Income) | B8: =MAX(0,'Tax Engine'!D13) -> 55678.79 | C8: Auto: B1 minus B6 (EPF). Verify with LHDN. | D8: Auto
A9: BAHAGIAN C — PELEPASAN (Tax Reliefs)
A10: Individu dan saudara tanggungan | B10: 9000 | C10: RM9,000 — automatic, pre-filled | D10: Auto
A11: Yuran pengajian — Kursus kemahiran (Terhad RM7,000) | B11: =MIN(SUMIF(Purchases!E7:E200,"Skills Course",Purchases!F7:F200),7000) -> 0 | C11: Skills courses, upskilling. Currently RM0 — update if you enroll | D11: Optional
A12: Gaya Hidup — WiFi + Phone + Books + Sukan (Terhad RM2,500) | B12: =MIN(SUMIF(Purchases!E7:E200,"Lifestyle-WiFi",Purchases!F7:F200)+SUMIF(Purchases!E7:E200,"Lifestyle-Phone/Book/Gadget",Purchases!F7:F200)+SUMIF(Purchases!E7:E200,"Lifestyle-Sports/Gym",Purchases!F7:F200),2500) -> 566.1 | C12: Your WiFi RM1,132 + phone RM1,368 = RM2,500 MAXED | D12: Claim
A13: Gaya Hidup Tambahan — Sukan (Terhad RM1,000) | B13: =MIN(SUMIF(Purchases!E7:E200,"Lifestyle-Sports/Gym",Purchases!F7:F200),1000) -> 0 | C13: EXTRA sports relief on top of RM2,500. Gym/equipment/competition. | D13: Optional
A14: Tabungan bersih SSPN (Terhad RM8,000) | B14: =MIN(SUMIF(Purchases!E7:E200,"SSPN",Purchases!F7:F200),8000) -> 0 | C14: Currently RM0 — HIGH IMPACT if you open SSPN account | D14: Optional
A15: Insurans nyawa + KWSP Sukarela (Terhad RM7,000 jumlah) | B15: =MIN(SUMIF(Purchases!E7:E200,"Life Insurance",Purchases!F7:F200),3000) -> 180 | C15: Your RM30/month = RM360. Limit RM3,000 for insurance portion | D15: Claim
A16: Skim PRS persaraan swasta (Terhad RM3,000) | B16: =MIN(SUMIF(Purchases!E7:E200,"PRS",Purchases!F7:F200),3000) -> 0 | C16: Currently RM0 — consider PRS fund contribution | D16: Optional
A17: Insurans pendidikan dan perubatan (Terhad RM4,000) | B17: =MIN(SUMIF(Purchases!E7:E200,"Medical Insurance",Purchases!F7:F200),4000) -> 0 | C17: Medical card premiums. Currently RM0 — consider upgrading insurance | D17: Optional
A18: Caruman PERKESO/SOCSO (Terhad RM350) | B18: =MIN(SUM('Salary Log'!E5:E16)+SUM('Salary Log'!F5:F16),350) -> 327.45 | C18: Your 2025 form showed RM181. 2026 ~RM237 based on salary. | D18: Claim
A19: Pemeriksaan perubatan / pergigian / dental (Terhad RM1,000) | B19: =MIN(SUMIF(Purchases!E7:E200,"Medical/Dental/Checkup",Purchases!F7:F200),1000) -> 0 | C19: Medical checkup, dental, vaccination — keep receipts | D19: Optional
A20: TOTAL PELEPASAN | B20: ='Tax Engine'!D23 -> 9979.35 | C20: Sum of all reliefs above | D20: Total
A21: REBAT & TOLAKAN
A22: Zakat dan Fitrah | B22: 0 | C22: Enter actual zakat paid — RM for RM tax deduction! | D22: Optional
A23: Levi Umrah (Terhad 2× seumur hidup) | B23: 0 | C23: Only if you performed umrah in 2026 | D23: Optional
A24: BAHAGIAN D — CUKAI & KEPUTUSAN (Result)
A25: Pendapatan Bercukai (Chargeable Income) | B25: ='Tax Engine'!D25 -> 45699.44 | C25: Statutory income minus all reliefs | D25: Auto
A26: Cukai atas Pendapatan Bercukai | B26: ='Tax Engine'!D26 -> 1241.9664 | C26: Tax on chargeable income using progressive bands | D26: Auto
A27: Tolak PCB — Potongan Cukai Bulanan | B27: ='PCB Schedule'!F16 -> 637.032 | C27: Total PCB deducted by employer all year. Verify vs MyTax. | D27: Mandatory
A28: BAKI CUKAI KENA DIBAYAR / LEBIHAN | B28: ='Tax Engine'!D34 -> 614.5164 | C28: POSITIVE = pay this by 30 Apr 2027. NEGATIVE = LHDN refunds you. Your 2025 balance was RM52.43. | D28: Result
A30: YOUR 2025 vs 2026 COMPARISON (Reference)
A31: 2025 Assessment Year Result | B31: RM 52.43 kena bayar | C31: Confirmed from your Borang BE 2025 | D31: Paid
A32: 2026 — Main salary only (est.) | B32: ='Tax Engine'!C34 -> 9.582 | C32: Without part-time income | D32: Estimated
A33: 2026 — With part-time Nuvera (est.) | B33: ='Tax Engine'!D34 -> 614.5164 | C33: Including ~RM19,000+ part-time | D33: Estimated
A34: Difference from declaring part-time | B34: =IF(ISNUMBER('Tax Engine'!D34),MAX(0,'Tax Engine'!D34-'Tax Engine'!C34),"Update Tax Engine") -> 604.9344 | C34: Extra tax owed due to part-time income | D34: Key figure

Sheet 2025 vs 2026
A1: 2025 ACTUAL vs 2026 ESTIMATED — BORANG BE COMPARISON
A2: 2025 figures from your actual submitted Borang BE. 2026 figures estimated from tracker.
A3: ⚠ NOTE: Your 2025 form shows RM2,362 under "Faedah/Lain-lain" income. This may be bank interest, part-time income, or other sources. Please confirm what this was — it affects how we compare 2025 vs 2026.
A4: Item | B4: 2025 Actual (RM) | C4: 2026 Main Only (Est.) | D4: 2026 + Part-time (Est.) | E4: Notes
A5: BAHAGIAN B — PENDAPATAN (Income)
A6: Pendapatan Penggajian (Employment) | B6: 36900 | C6: ='Tax Engine'!C5 -> 51600 | D6: ='Tax Engine'!D7 -> 61682.24 | E6: 2025: 1 employer. 2026: main salary + Nuvera part-time combined here
A7: Faedah / Lain-lain Income | B7: 2362 | C7: 0 | D7: 0 | E7: ⚠ Confirm what this RM2,362 was in 2025 — bank interest? part-time? Other?
A8: Pendapatan Agregat | B8: 39262 | C8: ='Tax Engine'!C7 -> 51600 | D8: ='Tax Engine'!D7 -> 61682.24 | E8: 2025: RM39,262. 2026 will be higher.
A9: Caruman KWSP / EPF | B9: 0 | C9: ='Tax Engine'!C9 -> 5676 | D9: ='Tax Engine'!C9 -> 5676 | E9: 2025: PCB=0, EPF=0 in form (pre-filled missing?). 2026: proper EPF deduction.
A10: Pendapatan Berkanun (Statutory Income) | B10: 36900 | C10: ='Tax Engine'!C13 -> 45596.55 | D10: ='Tax Engine'!D13 -> 55678.79 | E10: 2025 statutory = RM36,900 (employment only, no EPF deducted in form)
A11: BAHAGIAN C — PELEPASAN (Reliefs)
A12: Individu & saudara tanggungan | B12: 9000 | C12: 9000 | D12: 9000 | E12: Always RM9,000 — automatic
A13: Gaya Hidup (RM2,500 limit) | B13: 0 | C13: =MIN('Tax Engine'!C17,2500) -> 566.1 | D13: =MIN('Tax Engine'!D17,2500) -> 566.1 | E13: 2025: not claimed (RM0). 2026: WiFi+phone = RM2,500 MAXED
A14: Insurans Nyawa | B14: 0 | C14: =MIN(SUMIF(Purchases!E7:E200,"Life Insurance",Purchases!F7:F200),3000) -> 180 | D14: =MIN(SUMIF(Purchases!E7:E200,"Life Insurance",Purchases!F7:F200),3000) -> 180 | E14: 2025: not claimed. 2026: RM360 (RM30/month)
A15: SOCSO / PERKESO | B15: 181 | C15: =MIN(SUM('Salary Log'!E5:E16)+SUM('Salary Log'!F5:F16),350) -> 327.45 | D15: =MIN(SUM('Salary Log'!E5:E16)+SUM('Salary Log'!F5:F16),350) -> 327.45 | E15: 2025: RM181 claimed. 2026: ~RM237 expected.
A16: SSPN Savings | B16: 0 | C16: 0 | D16: 0 | E16: Not claimed in 2025 or 2026 yet — HIGH IMPACT if opened
A17: Medical/Dental/Checkup | B17: 0 | C17: =MIN(SUMIF(Purchases!E7:E200,"Medical/Dental/Checkup",Purchases!F7:F200),1000) -> 0 | D17: =MIN(SUMIF(Purchases!E7:E200,"Medical/Dental/Checkup",Purchases!F7:F200),1000) -> 0 | E17: Not claimed 2025. Claim in 2026 if you get a checkup.
A18: TOTAL PELEPASAN | B18: 9181 | C18: ='Tax Engine'!C23 -> 9979.35 | D18: ='Tax Engine'!D23 -> 9979.35 | E18: 2025: RM9,181. 2026 with new reliefs: higher.
A19: BAHAGIAN D — CUKAI & KEPUTUSAN (Tax Result)
A20: Pendapatan Bercukai (Chargeable) | B20: 27719 | C20: ='Tax Engine'!C25 -> 35617.2 | D20: ='Tax Engine'!D25 -> 45699.44 | E20: 2025: RM39,262 - RM9,181 reliefs - EPF = ~RM27,719
A21: Cukai atas Pendapatan Bercukai | B21: 61.43 | C21: ='Tax Engine'!C26 -> 637.032 | D21: ='Tax Engine'!D26 -> 1241.9664 | E21: 2025 actual tax: RM61.43 (very low — income in 1% band)
A22: Tolak PCB dibayar | B22: 0 | C22: ='PCB Schedule'!F16 -> 637.032 | D22: ='PCB Schedule'!F16 -> 637.032 | E22: 2025: PCB was RM0 (no deduction). 2026: RM627.45+ already paid.
A23: BAKI CUKAI KENA DIBAYAR | B23: 61.43 | C23: =IFERROR(MAX(0,'Tax Engine'!C34),0) -> 9.582 | D23: =IFERROR(MAX(0,'Tax Engine'!D34),0) -> 614.5164 | E23: 2025 PAID: RM61.43. 2026 with part-time: significantly higher.
A25: KEY INSIGHTS FROM YOUR 2025 FORM
A26: 1. PCB was RM0 in 2025 | B26: Your employer did NOT deduct PCB in 2025 at all. You paid the full RM61.43 yourself at e-Filing. In 2026, your employer IS deducting PCB (RM627.45 so far) — much better managed.
A27: 2. RM2,362 "Faedah/Lain-lain" needs clarification | B27: This unidentified income was declared in 2025. Was it bank interest? Part-time income? If it was informal part-time, it means you HAVE declared such income before — same applies to Nuvera in 2026.
A28: 3. Your total 2025 tax was only RM61.43 | B28: On RM39,262 aggregate income, you paid just RM61.43 in tax. That is 0.16% effective rate. In 2026 with part-time, expect ~RM1,500–2,000 more — still very low as a % of income.
A29: 4. You did NOT claim lifestyle, insurance or WiFi in 2025 | B29: In 2026 you are claiming RM2,500 lifestyle + RM360 insurance + RM237 SOCSO = RM3,097 extra reliefs. This alone saves you ~RM93 vs 2025. Keep building reliefs!
